{"uuid": "6eec0f9e-38dc-4006-a8fa-25e6b4234fae", "children": ["9f3ef4a0-7be2-4c62-b61a-90559ef1108a", "f9ad9d0d-4eb6-4a4c-99d6-4d932548dc1e", "ae2a210a-41c9-4059-b83f-f5f58385c691", "60ebeb8b-42bc-4683-b622-c8a61b511080"], "befores": [{"name": "init_web_driver", "status": "broken", "statusDetails": {"message": "selenium.common.exceptions.WebDriverException: Message: unknown error: net::ERR_CONNECTION_REFUSED\n  (Session info: chrome=114.0.5735.90)\n\n", "trace": "  File \"C:\\Users\\user\\AppData\\Roaming\\Python\\Python310\\site-packages\\pluggy\\_callers.py\", line 39, in _multicall\n    res = hook_impl.function(*args)\n  File \"C:\\Users\\user\\AppData\\Roaming\\Python\\Python310\\site-packages\\_pytest\\fixtures.py\", line 1130, in pytest_fixture_setup\n    result = call_fixture_func(fixturefunc, request, kwargs)\n  File \"C:\\Users\\user\\AppData\\Roaming\\Python\\Python310\\site-packages\\_pytest\\fixtures.py\", line 902, in call_fixture_func\n    fixture_result = next(generator)\n  File \"C:\\python-selenium\\FinalProject\\test_cases\\conftest.py\", line 34, in init_web_driver\n    driver.get((get_data('url')))\n  File \"C:\\Users\\user\\AppData\\Roaming\\Python\\Python310\\site-packages\\selenium\\webdriver\\support\\event_firing_webdriver.py\", line 78, in get\n    self._dispatch(\"navigate_to\", (url, self._driver), \"get\", (url, ))\n  File \"C:\\Users\\user\\AppData\\Roaming\\Python\\Python310\\site-packages\\selenium\\webdriver\\support\\event_firing_webdriver.py\", line 160, in _dispatch\n    raise e\n  File \"C:\\Users\\user\\AppData\\Roaming\\Python\\Python310\\site-packages\\selenium\\webdriver\\support\\event_firing_webdriver.py\", line 157, in _dispatch\n    result = getattr(self._driver, d_call)(*d_args)\n  File \"C:\\Users\\user\\AppData\\Roaming\\Python\\Python310\\site-packages\\selenium\\webdriver\\remote\\webdriver.py\", line 333, in get\n    self.execute(Command.GET, {'url': url})\n  File \"C:\\Users\\user\\AppData\\Roaming\\Python\\Python310\\site-packages\\selenium\\webdriver\\remote\\webdriver.py\", line 321, in execute\n    self.error_handler.check_response(response)\n  File \"C:\\Users\\user\\AppData\\Roaming\\Python\\Python310\\site-packages\\selenium\\webdriver\\remote\\errorhandler.py\", line 242, in check_response\n    raise exception_class(message, screen, stacktrace)\n"}, "start": 1685963728382, "stop": 1685963736456}], "start": 1685963728382, "stop": 1685963737500}